Workbook

Sheet PLANILHA FINAL
A1: Plano de Ação Autodignóstico de Atendimento dos Riscos Críticos Unidade | Três Marias
A2: Item | B2: Risco Crítico | C2: Nº do Requisito no protocolo | D2: Ação | E2: Área Priorizada | F2: Prazo Área priorizada | G2: Prazo Toda Unidade | H2: Responsável | I2: Status | K2: Observações
A3: 1 | B3: Trabalho em Altura* | C3: =IF(B3="","",_xlfn.MAXIFS($C$2:C2,$B$2:B2,B3)+1) -> 1 | E3: Á DEFINIR | G3: 46283 | I3: Concluído | J3: =IF(I3="Concluído",2,IF(I3="Andamento",1,IF(I3="Atrasado",0,""))) -> 2
A4: 2 | B4: Trabalho em Altura* | C4: =IF(B4="","",_xlfn.MAXIFS($C$2:C3,$B$2:B3,B4)+1) -> 2 | E4: Á DEFINIR | G4: 46283 | I4: Atrasado | J4: =IF(I4="Concluído",2,IF(I4="Andamento",1,IF(I4="Atrasado",0,""))) -> 0
A5: 3 | B5: Trabalho em Altura* | C5: =IF(B5="","",_xlfn.MAXIFS($C$2:C4,$B$2:B4,B5)+1) -> 3 | E5: Á DEFINIR | G5: 46283 | I5: Concluído | J5: =IF(I5="Concluído",2,IF(I5="Andamento",1,IF(I5="Atrasado",0,""))) -> 2
A6: 4 | B6: Trabalho em Altura* | C6: =IF(B6="","",_xlfn.MAXIFS($C$2:C5,$B$2:B5,B6)+1) -> 4 | E6: Á DEFINIR | G6: 46283 | I6: Concluído | J6: =IF(I6="Concluído",2,IF(I6="Andamento",1,IF(I6="Atrasado",0,""))) -> 2
A7: 5 | B7: Trabalho em Altura* | C7: =IF(B7="","",_xlfn.MAXIFS($C$2:C6,$B$2:B6,B7)+1) -> 5 | E7: Á DEFINIR | G7: 46283 | I7: Concluído | J7: =IF(I7="Concluído",2,IF(I7="Andamento",1,IF(I7="Atrasado",0,""))) -> 2
A8: 6 | B8: Trabalho em Altura* | C8: =IF(B8="","",_xlfn.MAXIFS($C$2:C7,$B$2:B7,B8)+1) -> 6 | E8: Á DEFINIR | G8: 46283 | I8: Concluído | J8: =IF(I8="Concluído",2,IF(I8="Andamento",1,IF(I8="Atrasado",0,""))) -> 2
A9: 7 | B9: Trabalho em Altura* | C9: =IF(B9="","",_xlfn.MAXIFS($C$2:C8,$B$2:B8,B9)+1) -> 7 | E9: Á DEFINIR | G9: 46283 | I9: Atrasado | J9: =IF(I9="Concluído",2,IF(I9="Andamento",1,IF(I9="Atrasado",0,""))) -> 0
A10: 8 | B10: Trabalho em Altura* | C10: =IF(B10="","",_xlfn.MAXIFS($C$2:C9,$B$2:B9,B10)+1) -> 8 | E10: Á DEFINIR | G10: 46283 | I10: Atrasado | J10: =IF(I10="Concluído",2,IF(I10="Andamento",1,IF(I10="Atrasado",0,""))) -> 0
A11: 9 | B11: Trabalho em Altura* | C11: =IF(B11="","",_xlfn.MAXIFS($C$2:C10,$B$2:B10,B11)+1) -> 9 | E11: Á DEFINIR | G11: 46283 | I11: Andamento | J11: =IF(I11="Concluído",2,IF(I11="Andamento",1,IF(I11="Atrasado",0,""))) -> 1
A12: 10 | B12: Trabalho em Altura* | C12: =IF(B12="","",_xlfn.MAXIFS($C$2:C11,$B$2:B11,B12)+1) -> 10 | E12: Á DEFINIR | G12: 46283 | I12: Andamento | J12: =IF(I12="Concluído",2,IF(I12="Andamento",1,IF(I12="Atrasado",0,""))) -> 1
A13: 11 | B13: Trabalho em Altura* | C13: =IF(B13="","",_xlfn.MAXIFS($C$2:C12,$B$2:B12,B13)+1) -> 11 | E13: Á DEFINIR | G13: 46283 | I13: Andamento | J13: =IF(I13="Concluído",2,IF(I13="Andamento",1,IF(I13="Atrasado",0,""))) -> 1
A14: 12 | B14: Trabalho em Altura* | C14: =IF(B14="","",_xlfn.MAXIFS($C$2:C13,$B$2:B13,B14)+1) -> 12 | E14: Á DEFINIR | G14: 46283 | I14: Andamento | J14: =IF(I14="Concluído",2,IF(I14="Andamento",1,IF(I14="Atrasado",0,""))) -> 1
... A122: 120 | B122: Liberação de Energia | C122: =IF(B122="","",_xlfn.MAXIFS($C$2:C121,$B$2:B121,B122)+1) -> 11 | E122: Á DEFINIR | G122: 46283 | I122: Andamento | J122: =IF(I122="Concluído",2,IF(I122="Andamento",1,IF(I122="Atrasado",0,""))) -> 1

Sheet Base de dados
B2: Risco crítico | C2: Total | D2: Concluído | E2: Andamento | F2: Vencido | G2: Total_Rótulo | H2: Conclusão | J2: Riscos sem conclusão
B3: Espaço Confinado | C3: =COUNTIF('PLANILHA FINAL'!$B:$B,B3) -> 10 | D3: =IF(C3=0,0,COUNTIFS('PLANILHA FINAL'!$B:$B,B3&"*",'PLANILHA FINAL'!$I:$I,"Concluído")/C3) -> 0.6 | E3: =IF(C3=0,0,COUNTIFS('PLANILHA FINAL'!$B:$B,B3&"*",'PLANILHA FINAL'!$I:$I,"Andamento")/C3) -> 0.2 | F3: =IF(C3=0,0,COUNTIFS('PLANILHA FINAL'!$B:$B,B3&"*",'PLANILHA FINAL'!$I:$I,"Atrasado")/C3) -> 0.2 | G3: =C3 -> 10 | H3: =IF(D2=0,"Sem conclusão","Com conclusão") -> Com conclusão | J3: =COUNTIF(Tabela2[Conclusão],"Sem conclusão") -> 2
B4: Produtos Químicos Perigosos | C4: =COUNTIF('PLANILHA FINAL'!$B:$B,B4) -> 10 | D4: =IF(C4=0,0,COUNTIFS('PLANILHA FINAL'!$B:$B,B4&"*",'PLANILHA FINAL'!$I:$I,"Concluído")/C4) -> 1 | E4: =IF(C4=0,0,COUNTIFS('PLANILHA FINAL'!$B:$B,B4&"*",'PLANILHA FINAL'!$I:$I,"Andamento")/C4) -> 0 | F4: =IF(C4=0,0,COUNTIFS('PLANILHA FINAL'!$B:$B,B4&"*",'PLANILHA FINAL'!$I:$I,"Atrasado")/C4) -> 0 | G4: =C4 -> 10 | H4: =IF(D4=0,"Sem conclusão","Com conclusão") -> Com conclusão | J4: =COUNTIF(Tabela2[Conclusão],"Sem conclusão")/COUNTA(Tabela2[Risco crítico]) -> 0.2
B5: Metal Líquido* | C5: =COUNTIF('PLANILHA FINAL'!$B:$B,B5) -> 11 | D5: =IF(C5=0,0,COUNTIFS('PLANILHA FINAL'!$B:$B,B5&"*",'PLANILHA FINAL'!$I:$I,"Concluído")/C5) -> 0.27272727 | E5: =IF(C5=0,0,COUNTIFS('PLANILHA FINAL'!$B:$B,B5&"*",'PLANILHA FINAL'!$I:$I,"Andamento")/C5) -> 0.63636364 | F5: =IF(C5=0,0,COUNTIFS('PLANILHA FINAL'!$B:$B,B5&"*",'PLANILHA FINAL'!$I:$I,"Atrasado")/C5) -> 0.090909091 | G5: =C5 -> 11 | H5: =IF(D5=0,"Sem conclusão","Com conclusão") -> Com conclusão
B6: Equipamentos Móveis* | C6: =COUNTIF('PLANILHA FINAL'!$B:$B,B6) -> 11 | D6: =IF(C6=0,0,COUNTIFS('PLANILHA FINAL'!$B:$B,B6&"*",'PLANILHA FINAL'!$I:$I,"Concluído")/C6) -> 0.63636364 | E6: =IF(C6=0,0,COUNTIFS('PLANILHA FINAL'!$B:$B,B6&"*",'PLANILHA FINAL'!$I:$I,"Andamento")/C6) -> 0.18181818 | F6: =IF(C6=0,0,COUNTIFS('PLANILHA FINAL'!$B:$B,B6&"*",'PLANILHA FINAL'!$I:$I,"Atrasado")/C6) -> 0.18181818 | G6: =C6 -> 11 | H6: =IF(D6=0,"Sem conclusão","Com conclusão") -> Com conclusão | J6: Riscos com conclusão
B7: Liberação de Energia | C7: =COUNTIF('PLANILHA FINAL'!$B:$B,B7) -> 11 | D7: =IF(C7=0,0,COUNTIFS('PLANILHA FINAL'!$B:$B,B7&"*",'PLANILHA FINAL'!$I:$I,"Concluído")/C7) -> 0.27272727 | E7: =IF(C7=0,0,COUNTIFS('PLANILHA FINAL'!$B:$B,B7&"*",'PLANILHA FINAL'!$I:$I,"Andamento")/C7) -> 0.54545455 | F7: =IF(C7=0,0,COUNTIFS('PLANILHA FINAL'!$B:$B,B7&"*",'PLANILHA FINAL'!$I:$I,"Atrasado")/C7) -> 0.18181818 | G7: =C7 -> 11 | H7: =IF(D7=0,"Sem conclusão","Com conclusão") -> Com conclusão | J7: =COUNTIF(Tabela2[Conclusão],"Com conclusão") -> 8
B8: Trabalho em Altura* | C8: =COUNTIF('PLANILHA FINAL'!$B:$B,B8) -> 13 | D8: =IF(C8=0,0,COUNTIFS('PLANILHA FINAL'!$B:$B,B8&"*",'PLANILHA FINAL'!$I:$I,"Concluído")/C8) -> 0.38461538 | E8: =IF(C8=0,0,COUNTIFS('PLANILHA FINAL'!$B:$B,B8&"*",'PLANILHA FINAL'!$I:$I,"Andamento")/C8) -> 0.38461538 | F8: =IF(C8=0,0,COUNTIFS('PLANILHA FINAL'!$B:$B,B8&"*",'PLANILHA FINAL'!$I:$I,"Atrasado")/C8) -> 0.23076923 | G8: =C8 -> 13 | H8: =IF(D8=0,"Sem conclusão","Com conclusão") -> Com conclusão | J8: =COUNTIF(Tabela2[Conclusão],"Com conclusão")/COUNTA(Tabela2[Risco crítico]) -> 0.8
B9: Sistemas Pressurizados* | C9: =COUNTIF('PLANILHA FINAL'!$B:$B,B9) -> 13 | D9: =IF(C9=0,0,COUNTIFS('PLANILHA FINAL'!$B:$B,B9&"*",'PLANILHA FINAL'!$I:$I,"Concluído")/C9) -> 0 | E9: =IF(C9=0,0,COUNTIFS('PLANILHA FINAL'!$B:$B,B9&"*",'PLANILHA FINAL'!$I:$I,"Andamento")/C9) -> 0.076923077 | F9: =IF(C9=0,0,COUNTIFS('PLANILHA FINAL'!$B:$B,B9&"*",'PLANILHA FINAL'!$I:$I,"Atrasado")/C9) -> 0.92307692 | G9: =C9 -> 13 | H9: =IF(D9=0,"Sem conclusão","Com conclusão") -> Sem conclusão
B10: Veículos Automotores | C10: =COUNTIF('PLANILHA FINAL'!$B:$B,B10) -> 13 | D10: =IF(C10=0,0,COUNTIFS('PLANILHA FINAL'!$B:$B,B10&"*",'PLANILHA FINAL'!$I:$I,"Concluído")/C10) -> 0 | E10: =IF(C10=0,0,COUNTIFS('PLANILHA FINAL'!$B:$B,B10&"*",'PLANILHA FINAL'!$I:$I,"Andamento")/C10) -> 1 | F10: =IF(C10=0,0,COUNTIFS('PLANILHA FINAL'!$B:$B,B10&"*",'PLANILHA FINAL'!$I:$I,"Atrasado")/C10) -> 0 | G10: =C10 -> 13 | H10: =IF(D10=0,"Sem conclusão","Com conclusão") -> Sem conclusão
B11: Carga Suspensa* | C11: =COUNTIF('PLANILHA FINAL'!$B:$B,B11) -> 14 | D11: =IF(C11=0,0,COUNTIFS('PLANILHA FINAL'!$B:$B,B11&"*",'PLANILHA FINAL'!$I:$I,"Concluído")/C11) -> 0.5 | E11: =IF(C11=0,0,COUNTIFS('PLANILHA FINAL'!$B:$B,B11&"*",'PLANILHA FINAL'!$I:$I,"Andamento")/C11) -> 0.35714286 | F11: =IF(C11=0,0,COUNTIFS('PLANILHA FINAL'!$B:$B,B11&"*",'PLANILHA FINAL'!$I:$I,"Atrasado")/C11) -> 0.14285714 | G11: =C11 -> 14 | H11: =IF(D11=0,"Sem conclusão","Com conclusão") -> Com conclusão
B12: Eletricidade | C12: =COUNTIF('PLANILHA FINAL'!$B:$B,B12) -> 14 | D12: =IF(C12=0,0,COUNTIFS('PLANILHA FINAL'!$B:$B,B12&"*",'PLANILHA FINAL'!$I:$I,"Concluído")/C12) -> 0.21428571 | E12: =IF(C12=0,0,COUNTIFS('PLANILHA FINAL'!$B:$B,B12&"*",'PLANILHA FINAL'!$I:$I,"Andamento")/C12) -> 0.28571429 | F12: =IF(C12=0,0,COUNTIFS('PLANILHA FINAL'!$B:$B,B12&"*",'PLANILHA FINAL'!$I:$I,"Atrasado")/C12) -> 0.5 | G12: =C12 -> 14 | H12: =IF(D12=0,"Sem conclusão","Com conclusão") -> Com conclusão

Sheet Calculos_Aux
D4: Indicador | E4: Valor
D5: Total de Ações | E5: =COUNTA('PLANILHA FINAL'!$A:$A)-2 -> 120
D6: Concluídas | E6: =COUNTIF('PLANILHA FINAL'!$I:$I,"Concluído") -> 44
D7: Em Andamento | E7: =COUNTIF('PLANILHA FINAL'!$I:$I,"Andamento") -> 45
D8: Vencidas | E8: =COUNTIF('PLANILHA FINAL'!$I:$I,"Atrasado") -> 31
D9: % Conclusão | E9: =COUNTIF('PLANILHA FINAL'!$I:$I,"Concluído")/(COUNTA('PLANILHA FINAL'!$A:$A)-2) -> 0.36666667
D10: % Atraso | E10: =COUNTIF('PLANILHA FINAL'!$I:$I,"Atrasado")/(COUNTA('PLANILHA FINAL'!$A:$A)-2) -> 0.25833333
D11: % Andamento | E11: =COUNTIF('PLANILHA FINAL'!$I:$I,"Andamento")/(COUNTA('PLANILHA FINAL'!$A:$A)-2) -> 0.375
D16: =TODAY() -> 46284

Sheet Dashboard

Sheet Planilha1
A1: Plano de Ação Autodignóstico de Atendimento dos Riscos Críticos Unidade | Três Marias
A2: Ítem | B2: Risco Crítico | C2: Número do Requisito no protocolo | D2: Categoria do Requisito | E2: Ação | F2: Área Priorizada | G2: Prazo Área priorizada | H2: Prazo Toda Unidade | I2: Responsável | J2: Status | L2: Necessário CAPEX Investimento? | M2: Observações
A3: 1 | B3: Equip. Móveis | C3: 6 | D3: Instalações e Equipamentos | E3: Possui 91 equipamentos mobilizados, sendo que somente 1 que está com mais de 15 anos. Ação: Adequar veículo que está com mais de 15 anos de utilização, PH Intralogistica. | F3: xxxxxxxxxxxxxxxxxxx | I3: xxxxxxxxxxxx | J3: Andamento | K3: =IF(J3="Concluído",2,IF(J3="Andamento",1,IF(J3="Atrasado",0,""))) -> 1 | L3: NÂO | M3: xxxxxxx
A4: 2 | B4: Equip. Móveis | C4: 10 | D4: Instalações e Equipamentos | E4: Equipamento Bob Cat, tag: MPC-035, não possui cabine climatizada. Ação adequar e ou substituir equipamento TAG MPC-035 com cabine climatizada, PH Intralogistica. | J4: Concluído | K4: =IF(J4="Concluído",2,IF(J4="Andamento",1,IF(J4="Atrasado",0,""))) -> 2
A5: 3 | B5: Equip. Móveis | C5: 10 | D5: Instalações e Equipamentos | E5: Não possui rádio de comunicação em todos equipamentos; Ação: Adequar rádio de comunicação em todos equipamentos móveis, PH Intralogistica. | J5: Atrasado | K5: =IF(J5="Concluído",2,IF(J5="Andamento",1,IF(J5="Atrasado",0,""))) -> 0
A6: 4 | B6: Equip. Móveis | C6: 29 | D6: Pessoas | E6: Plano de transito, Item em andamento, considerar trabalho da Unidade em andamento. Ação: Adequar plano de transito da Unidade. | K6: =IF(J6="Concluído",2,IF(J6="Andamento",1,IF(J6="Atrasado",0,"")))
A7: 5 | B7: Equip. Móveis | C7: 33 | D7: Instalações e Equipamentos | E7: Atualmente 65% dos veículos da PH possuem sensor de fadiga, estão ligados a atividade de remoção e os demais 35% não possuem controle. Ação: Implantart sistema de fadiga nos equipamentos vinculados ao contrato, PH Intralogistica. | K7: =IF(J7="Concluído",2,IF(J7="Andamento",1,IF(J7="Atrasado",0,"")))
A8: 6 | B8: Equip. Móveis | C8: 40 | D8: Instalações e Equipamentos | E8: Atualmente a empresa não possui equipamento para manipular pneus, atualmente se faz de forma manual.Ação: Adequar sistema para minipulação de pneu, PH Instralogistica. | K8: =IF(J8="Concluído",2,IF(J8="Andamento",1,IF(J8="Atrasado",0,"")))
A9: 7 | B9: Espaço Confinado | C9: 5 | D9: Instalações e Equipamentos | E9: Necessário avaliar o controle do inventário de espaços confinados e as respectivas Fichas de Caracterização de Espaço Confinado, garantindo que estejam atualizados, completos e em conformidade com os requisitos aplicáveis. | F9: Metalurgia | G9: 46568 | H9: 46751 | I9: Gabriel Alves De Oliveira Silva | J9: Andamento | K9: =IF(J9="Concluído",2,IF(J9="Andamento",1,IF(J9="Atrasado",0,""))) -> 1
A10: 8 | B10: Espaço Confinado | C10: 7 | D10: Pessoas | E10: Realizar a revisão do inventário de espaços confinados, garantindo que cada espaço confinado possua plano de resgate definido e devidamente vinculado ao respectivo cadastro, considerando suas características, riscos, acessos e condições para realização do resgate. | F10: Hidrometalurgia | G10: 46418 | H10: 46568 | I10: Larissa Tamires Pereira Rufino | J10: Andamento | K10: =IF(J10="Concluído",2,IF(J10="Andamento",1,IF(J10="Atrasado",0,""))) -> 1 | L10: NÂO | M10: Necessário contratação de uma empresa para levantemento dos dados
A11: 9 | B11: Espaço Confinado | C11: 17 | D11: Pessoas | E11: Necessário identificar o espaço confinado com TAG, garantindo sua rastreabilidade e vinculação ao inventário e à Ficha de Caracterização de Espaço Confinado. | F11: Hidrometalurgia | G11: 46418 | H11: 46203 | I11: Gilton Moreira Da Silva | J11: Andamento | K11: =IF(J11="Concluído",2,IF(J11="Andamento",1,IF(J11="Atrasado",0,""))) -> 1 | L11: NÂO
A12: 10 | B12: Espaço Confinado | C12: 20 | D12: Procedimento/Gestão | E12: Revisar o procedimento de limpeza das células, contemplando a atividade de retirada e coleta de resíduos acumulados no interior da célula, incluindo as etapas, riscos e controles necessários para sua execução, como isolamento e sinalização da área e avaliação da necessidade de utilização do sistema de exaustão. | F12: Eletrólise sala D | G12: 46387 | H12: 46387 | I12: Gabriel Alves De Oliveira Silva | J12: Andamento | K12: =IF(J12="Concluído",2,IF(J12="Andamento",1,IF(J12="Atrasado",0,""))) -> 1 | L12: NÂO
A13: 11 | B13: Carga Suspensa | C13: 5 | D13: Instalações e Equipamentos | E13: Reestabelecer gestão de cargas suspensas contemplando inventário e projetos dos equipamento e acessórios | F13: Eletrólise | G13: Á definir | H13: Á definir | I13: Facilitadores de área | J13: Andamento | K13: =IF(J13="Concluído",2,IF(J13="Andamento",1,IF(J13="Atrasado",0,""))) -> 1 | L13: NÂO
A14: 12 | B14: Carga Suspensa | C14: 16 | D14: Instalações e Equipamentos | E14: Propor forúm interno para avaliar a instalação de controle remoto para as talhas eletricas da na unidade | F14: Á definir | G14: Á definir | H14: Á definir | I14: Richard Silva | J14: Andamento | K14: =IF(J14="Concluído",2,IF(J14="Andamento",1,IF(J14="Atrasado",0,""))) -> 1 | L14: NÂO
A15: 13 | B15: Carga Suspensa | C15: 17 | D15: Instalações e Equipamentos | E15: Realizar estudo para adequar as talhas e pontes conforme norma (Item 17) | F15: Á definir | G15: Á definir | H15: Á definir | I15: Á definir | J15: Andamento | K15: =IF(J15="Concluído",2,IF(J15="Andamento",1,IF(J15="Atrasado",0,""))) -> 1 | L15: SIM
A16: 14 | B16: Carga Suspensa | C16: 20 | D16: Procedimento/Gestão | E16: Definir e divulgar padrão para controle de documentos (controle de arquivamento de check list´s) | F16: SSO | G16: Á definir | H16: Á definir | I16: Marcelo Magalhães ( com apoio da gestão - CBI) | J16: Andamento | K16: =IF(J16="Concluído",2,IF(J16="Andamento",1,IF(J16="Atrasado",0,""))) -> 1 | L16: NÂO
A17: 15 | B17: Eletricidade | C17: 5 | D17: Instalações e Equipamentos | E17: Avaliar e incluir no plano plurianual de inventimentos da Unidade associado a iniciativa já existente de adequações da NR-10 ( Retroalimentar o processo) - Adequação das Sala Elétrica da Cal / Bandeijamento danificados / corridos sala elétrica da filtração e presença de infiltração na mesma e adequação da climatização da mesma | F17: Sala Elétrica da Cal - Efluentes Sala Elétrica - Filtração | G17: Ver plano de investimentos NR-10 | I17: Adelmo Nogueira | J17: Andamento | K17: =IF(J17="Concluído",2,IF(J17="Andamento",1,IF(J17="Atrasado",0,""))) -> 1 | L17: SIM | M17: Plano de adequação já em andamento. Equipe de Sustaining atuando na Fundição de Borras e Lucas irá atualizar o cronograma da Unidade, mas requer inserir este pontos
A18: 16 | B18: Eletricidade | C18: 5 | D18: Instalações e Equipamentos | E18: Fazer avaliação in loco com time de PCM para implementar ação de contigência referente a infiltração na sala elétrica da Filtração de Zinco | F18: Sala Elétrica - Filtração | G18: 30 dias | H18: NA | I18: Thiago Alves | J18: Andamento | K18: =IF(J18="Concluído",2,IF(J18="Andamento",1,IF(J18="Atrasado",0,""))) -> 1 | L18: NÂO
A19: 17 | B19: Eletricidade | C19: 6 | D19: Instalações e Equipamentos | E19: Disponibilizar diagramas elétricos nas salas elétricas - Ausente na Sala Elétrica da Cal - Efluentes | F19: Sala Elétrica da Cal - Efluentes | G19: 15 dias | I19: Thiago Alves | J19: Andamento | K19: =IF(J19="Concluído",2,IF(J19="Andamento",1,IF(J19="Atrasado",0,""))) -> 1 | L19: NÂO | M19: Partindo da premissa de diagramas existentes
A20: 18 | B20: Eletricidade | C20: 8 | D20: Instalações e Equipamentos | E20: Solicitar inserção no relatório da empresa contrata para fazer teste de equipamentos / Instrumentos de tópico com registro da inutilização e destinação dos equipamentos e instrumentos que não passarem nos testes funcionais - Tópico ausente no relatório 2025 | F20: Subestaçao Eletrica Principal | G20: Imediato | H20: Imediato | I20: Luís Felipe | J20: Andamento | K20: =IF(J20="Concluído",2,IF(J20="Andamento",1,IF(J20="Atrasado",0,""))) -> 1 | L20: NÂO | M20: Luís já solicitou a empresa PPI que fará os testes - Agosto 2026
A21: 19 | B21: Eletricidade | C21: 10 | D21: Instalações e Equipamentos | E21: Mesma trativa item 1 | F21: Sala Elétrica da Cal - Efluentes Sala Elétrica - Filtração | G21: Ver plano de investimentos NR-10 | I21: Adelmo Nogueira | J21: Andamento | K21: =IF(J21="Concluído",2,IF(J21="Andamento",1,IF(J21="Atrasado",0,""))) -> 1 | L21: SIM | M21: Plano de adequação já em andamento. Equipe de Sustaining atuando no tema irá atualizar o cronograma de investimentos da Unidade, mas requer inserir este pontos
A22: 20 | B22: Eletricidade | C22: 11 | D22: Instalações e Equipamentos | E22: Concluir estudo de áreas classificadas da Unidade | F22: Purificação / Fundição / OZ e ET | G22: Ver plano de investimentos NR-20 | I22: Lucas Borges | J22: Andamento | K22: =IF(J22="Concluído",2,IF(J22="Andamento",1,IF(J22="Atrasado",0,""))) -> 1 | L22: SIM | M22: Plano de adequação já em andamento. Equipe de Sustaining atuando no tema irá atualizar o cronograma de investimentos da Unidade, mas requer inserir este pontos
A23: 21 | B23: Eletricidade | C23: 14 | D23: Instalações e Equipamentos | E23: Mesma trativa item 3 | F23: Sala Elétrica da Cal - Efluentes | G23: 15 dias | I23: Thiago Alves | J23: Andamento | K23: =IF(J23="Concluído",2,IF(J23="Andamento",1,IF(J23="Atrasado",0,""))) -> 1 | L23: SIM
A24: 22 | B24: Eletricidade | C24: 15 | D24: Instalações e Equipamentos | E24: Divulgar periodicamente em DDS e/ou Comitê de instalaçoes elétrica tema especifico referente a localização do prontuário de instalações elétrica | F24: Equipe Elétrica Unidade | G24: 30 dias | H24: NA | I24: Luís Felipe | J24: Andamento | K24: =IF(J24="Concluído",2,IF(J24="Andamento",1,IF(J24="Atrasado",0,""))) -> 1 | L24: NÂO
A25: 23 | B25: Eletricidade | C25: 16 | D25: Instalações e Equipamentos | E25: Revisitar projeto de adequação de SPDA da Unidade - São 22 pontos SPDA que são avaliados via planos do SAP, porém existe em andamento plano de adequação do SPDA. | F25: Seguir planejamento priorização da Unidade | G25: Ver plano de investimentos NR-10 | I25: Adelmo Nogueira | J25: Andamento | K25: =IF(J25="Concluído",2,IF(J25="Andamento",1,IF(J25="Atrasado",0,""))) -> 1 | L25: SIM | M25: Plano de adequação já em andamento. Equipe de Sustaining atuando no tema irá atualizar o cronograma de investimentos da Unidade, mas requer inserir este pontos
A26: 24 | B26: Eletricidade | C26: 17 | D26: Instalações e Equipamentos | E26: Concluir estudo de áreas classificadas da Unidade | F26: Purificação / Fundição / OZ e ET | G26: Ver plano de investimentos NR-20 | I26: Lucas Borges | J26: Andamento | K26: =IF(J26="Concluído",2,IF(J26="Andamento",1,IF(J26="Atrasado",0,""))) -> 1 | L26: SIM | M26: Plano de adequação já em andamento. Equipe de Sustaining atuando no tema irá atualizar o cronograma de investimentos da Unidade, mas requer inserir este pontos
A27: 25 | B27: Eletricidade | C27: 18 | D27: Instalações e Equipamentos | E27: Ação de Contigência - Revisitar procedimentos de manutenção áreas criticas da Unidade e inserir cuidados sobre atividades em áreas classificadas baseado nas informações existentes | F27: Purificação / Fundição / OZ e ET | G27: 45 dias | I27: Luis Felipe | J27: Andamento | K27: =IF(J27="Concluído",2,IF(J27="Andamento",1,IF(J27="Atrasado",0,""))) -> 1 | L27: SIM | M27: Plano de adequação já em andamento. Equipe de Sustaining atuando no tema irá atualizar o cronograma de investimentos da Unidade, mas requer inserir este pontos
A28: 26 | B28: Eletricidade | C28: 18 | D28: Instalações e Equipamentos | E28: Ação definitiva - Concluir estudo de áreas classificadas da Unidade para posterior revisão dos procedimentos de manutenção | F28: Purificação / Fundição / OZ e ET | G28: Ver plano de investimentos NR-20 | I28: Lucas Borges | J28: Andamento | K28: =IF(J28="Concluído",2,IF(J28="Andamento",1,IF(J28="Atrasado",0,""))) -> 1 | L28: SIM | M28: Plano de adequação já em andamento. Equipe de Sustaining atuando no tema irá atualizar o cronograma de investimentos da Unidade, mas requer inserir este pontos
A29: 27 | B29: Eletricidade | C29: 19 | D29: Procedimento/Gestão | E29: Implementar diretriz de nova (APR/IPERC) de acordo com a OPS de segurança da Unidade | F29: Eletrólise / Turno Letra C - Manutenção | G29: 30 dias | H29: 46295 | I29: Tiago Henrique | J29: Andamento | K29: =IF(J29="Concluído",2,IF(J29="Andamento",1,IF(J29="Atrasado",0,""))) -> 1
A30: 28 | B30: Eletricidade | C30: 21 | D30: Procedimento/Gestão | E30: Avaliar e incluir no plano plurianual de inventimentos da Unidade associado a iniciativa já existente de adequações da NR-10 ( Retroalimentar o processo) - ) as-built / desenhos de linhas subterrâneas não exitem de forma sistematizada e disponiveis para consulta de todos executantes. | F30: Sala Elétrica da Cal - Efluentes Sala Elétrica - Filtração | G30: Ver plano de investimentos NR-10 | I30: Adelmo Nogueira | J30: Andamento | K30: =IF(J30="Concluído",2,IF(J30="Andamento",1,IF(J30="Atrasado",0,""))) -> 1 | L30: SIM | M30: Plano de adequação já em andamento. Equipe de Sustaining atuando no tema irá atualizar o cronograma de investimentos da Unidade, mas requer inserir este pontos
A31: 29 | B31: Eletricidade | C31: 27 | D31: Procedimento/Gestão | E31: Avaliar e incluir no plano plurianual de inventimentos da Unidade associado a iniciativa já existente de adequações da NR-10 ( Retroalimentar o processo) - Adequação das Sala Elétrica da Cal - Efluentes - Não apresenta condições técnicas adequadas para bloqueio e teste de energia zero de acordo com as práticas seguras previstas | F31: Sala Elétrica da Cal - Efluentes | G31: Ver plano de investimentos NR-10 | I31: Adelmo Nogueira | J31: Andamento | K31: =IF(J31="Concluído",2,IF(J31="Andamento",1,IF(J31="Atrasado",0,""))) -> 1 | L31: SIM | M31: Plano de adequação já em andamento. Equipe de Sustaining atuando na Fundição de Borras e Lucas irá atualizar o cronograma da Unidade, mas requer inserir este pontos
A32: 30 | B32: Eletricidade | C32: 29 | D32: Procedimento/Gestão | E32: Nos processo de bloqueio o protocolo traz a premissa de Permissões para trabalho validas por um dia - Implementar processo de PETAR que esta mapeado dentro da OPS de Segurança 2026 | F32: Unidade | G32: 60 dias | H32: 46295 | I32: Tiago Henrique | J32: Andamento | K32: =IF(J32="Concluído",2,IF(J32="Andamento",1,IF(J32="Atrasado",0,""))) -> 1
A33: 31 | B33: Eletricidade | C33: 29 | D33: Procedimento/Gestão | E33: Nos processo de bloqueio o protocolo traz a premissa de check para Restabelecimento de Energia - Analisar criticamente procedimento de bloqueio da Unidade e cuidados ainda não descritos no mesmo | F33: Unidade | G33: 60 dias | H33: 46295 | I33: José Luiz | J33: Andamento | K33: =IF(J33="Concluído",2,IF(J33="Andamento",1,IF(J33="Atrasado",0,""))) -> 1
A34: 32 | B34: Eletricidade | C34: 3 | D34: Pessoas | E34: Concluir projeto de automatização de crachá para atender ao requisito do protocolo referente a data de treinamento nos crachás de autorização para trabalho para equipe de elétrica - Será feito via QR code | F34: Unidade | G34: 60 dias | H34: 46295 | I34: Any | J34: Andamento | K34: =IF(J34="Concluído",2,IF(J34="Andamento",1,IF(J34="Atrasado",0,""))) -> 1
A35: 33 | B35: Prod.Quim.Perigosos | C35: 4 | D35: Pessoas | E35: Identificar e difundir a DD-TM-SSM-GST-102-PT-Tabela de Incompatibilidade Química, conforme procedimento específico PGU-TM-SSM-GST-024-PT - Gestão de Produtos Quimicos | F35: Fábrica de Ácido | G35: 46295 | H35: 46356 | I35: Hemilly Aparecida Pereira Gomes | J35: Atrasado | K35: =IF(J35="Concluído",2,IF(J35="Andamento",1,IF(J35="Atrasado",0,""))) -> 0 | L35: NÂO | M35: Divulgar a Tabela de Incompatibilidade Química
A36: 34 | B36: Prod.Quim.Perigosos | C36: 4 | D36: Pessoas | E36: Inserir a Tabela de Incompatibilidade Química no Treinamento de Ambientação para novos parceiros e novos empregados | F36: DHO - Treinamentos | G36: 46295 | H36: 46295 | I36: Daisy Cordeiro | J36: Andamento | K36: =IF(J36="Concluído",2,IF(J36="Andamento",1,IF(J36="Atrasado",0,""))) -> 1 | L36: NÂO | M36: Inserindo a tabela no material padrão de treinamentos
A37: 35 | B37: Prod.Quim.Perigosos | C37: 7 | D37: Instalações e Equipamentos | E37: Solicitar estudo de SPDA, para as unidades que armazenam produtos químicos inflamáveis | F37: Fábrica de Ácidos - tanque de armazenamento de diesel | G37: 46295 | H37: 46295 | I37: Luis Felipe Pereira | J37: Andamento | K37: =IF(J37="Concluído",2,IF(J37="Andamento",1,IF(J37="Atrasado",0,""))) -> 1 | L37: NÂO | M37: Ação contida no Protocolo de Atividades Críticas para Energia
A38: 36 | B38: Prod.Quim.Perigosos | C38: 7 | D38: Instalações e Equipamentos | E38: Instalar tranca no armazenamento de produtos controlados | F38: Laboratório Central - Armazenamento de Inflamáveis | G38: 46264 | H38: 46264 | I38: Raimundo Lima | J38: Andamento | K38: =IF(J38="Concluído",2,IF(J38="Andamento",1,IF(J38="Atrasado",0,""))) -> 1 | L38: NÂO | M38: Armario de Inflamáveis possui tranca, mas estava destrancado
A39: 37 | B39: Prod.Quim.Perigosos | C39: 7 | D39: Instalações e Equipamentos | E39: Divulgar a necessidade de manter chuveiros lava olhos, Diphoterine, e demais recursos de emergência bem sinalizados e com acesso desbloqueados | F39: Almoxarifado de Produtos Químicos | G39: 46264 | H39: 46264 | I39: Anaur Teixeira | J39: Andamento | K39: =IF(J39="Concluído",2,IF(J39="Andamento",1,IF(J39="Atrasado",0,""))) -> 1 | L39: NÂO | M39: Providenciar uma sinalização no piso e parede para manter acessos desobstruídos
A40: 38 | B40: Prod.Quim.Perigosos | C40: 7 | D40: Instalações e Equipamentos | E40: Fazer estudo de dissipação de vazamento de gases | F40: Fábrica de Ácidos e Ustulação | G40: 46356 | H40: 46356 | I40: Geraldo Cardoso | J40: Andamento | K40: =IF(J40="Concluído",2,IF(J40="Andamento",1,IF(J40="Atrasado",0,""))) -> 1 | L40: SIM | M40: Estudo de Dissipação de vazamento de gases para priorizar a aquisição e instalação de medidores fixos
...

Sheet ELETRICIDADE
